DEBUG:net "Connection established" (File "networking.py", line 265)
WARNING:net "Allowing any connection to the server. Disable for production!" (File "networking.py", line 38)
DEBUG:net "Starting server" (File "networking.py", line 233)
DEBUG:net "Server started at tcp://*:5000" (File "networking.py", line 241)
DEBUG:net "Received something from 00bd1b58ba" (File "networking.py", line 132)
DEBUG:net "Acknowledging connection" (File "networking.py", line 158)
DEBUG:net "Connection established" (File "networking.py", line 265)
WARNING:asyncio "Executing <Task pending name='Task-2' coro=<Kernel.dispatch_queue() running at /home/finn/.pyenv/versions/3.10.11/envs/cuda_ml/lib/python3.10/site-packages/ipykernel/kernelbase.py:516> wait_for=<Future pending cb=[Task.task_wakeup()] created at /home/finn/.pyenv/versions/3.10.11/envs/cuda_ml/lib/python3.10/site-packages/tornado/queues.py:248> cb=[IOLoop.add_future.<locals>.<lambda>() at /home/finn/.pyenv/versions/3.10.11/envs/cuda_ml/lib/python3.10/site-packages/tornado/ioloop.py:685]> took 0.344 seconds" (File "base_events.py", line 1904)
WARNING:asyncio "Executing <Task pending name='Task-2' coro=<Kernel.dispatch_queue() running at /home/finn/.pyenv/versions/3.10.11/envs/cuda_ml/lib/python3.10/site-packages/ipykernel/kernelbase.py:516> wait_for=<Future pending cb=[Task.task_wakeup()] created at /home/finn/.pyenv/versions/3.10.11/envs/cuda_ml/lib/python3.10/site-packages/tornado/queues.py:248> cb=[IOLoop.add_future.<locals>.<lambda>() at /home/finn/.pyenv/versions/3.10.11/envs/cuda_ml/lib/python3.10/site-packages/tornado/ioloop.py:685]> took 0.109 seconds" (File "base_events.py", line 1904)
WARNING:net "Allowing any connection to the server. Disable for production!" (File "networking.py", line 38)
DEBUG:net "Starting server" (File "networking.py", line 233)
DEBUG:net "Server started at tcp://*:5000" (File "networking.py", line 241)
DEBUG:net "Received something from 00bd1b58ba" (File "networking.py", line 132)
DEBUG:net "Acknowledging connection" (File "networking.py", line 158)
DEBUG:net "Connection established" (File "networking.py", line 265)
